{"name": "Actualizar informacion del perfil", "status": "broken", "statusDetails": {"message": "requests.exceptions.ConnectionError: ('Connection aborted.', ConnectionResetError(10054, 'Se ha forzado la interrupción de una conexión existente por el host remoto', None, 10054, None))\n", "trace": "  File \"C:\\Users\\Camilo\\AppData\\Local\\Programs\\Python\\Python312\\Lib\\site-packages\\behave\\model.py\", line 1329, in run\n    match.run(runner.context)\n  File \"C:\\Users\\Camilo\\AppData\\Local\\Programs\\Python\\Python312\\Lib\\site-packages\\behave\\matchers.py\", line 98, in run\n    self.func(context, *args, **kwargs)\n  File \"steps\\user_profile.py\", line 61, in validate_profile\n    response = requests.get(end_point)\n               ^^^^^^^^^^^^^^^^^^^^^^^\n  File \"C:\\Users\\Camilo\\AppData\\Local\\Programs\\Python\\Python312\\Lib\\site-packages\\requests\\api.py\", line 73, in get\n    return request(\"get\", url, params=params, **kwargs)\n           ^^^^^^^^^^^^^^^^^^^^^^^^^^^^^^^^^^^^^^^^^^^^\n  File \"C:\\Users\\Camilo\\AppData\\Local\\Programs\\Python\\Python312\\Lib\\site-packages\\requests\\api.py\", line 59, in request\n    return session.request(method=method, url=url, **kwargs)\n           ^^^^^^^^^^^^^^^^^^^^^^^^^^^^^^^^^^^^^^^^^^^^^^^^^\n  File \"C:\\Users\\Camilo\\AppData\\Local\\Programs\\Python\\Python312\\Lib\\site-packages\\requests\\sessions.py\", line 589, in request\n    resp = self.send(prep, **send_kwargs)\n           ^^^^^^^^^^^^^^^^^^^^^^^^^^^^^^\n  File \"C:\\Users\\Camilo\\AppData\\Local\\Programs\\Python\\Python312\\Lib\\site-packages\\requests\\sessions.py\", line 703, in send\n    r = adapter.send(request, **kwargs)\n        ^^^^^^^^^^^^^^^^^^^^^^^^^^^^^^^\n  File \"C:\\Users\\Camilo\\AppData\\Local\\Programs\\Python\\Python312\\Lib\\site-packages\\requests\\adapters.py\", line 501, in send\n    raise ConnectionError(err, request=request)\n"}, "steps": [{"name": "Given que exista un usuario con ID 1", "status": "broken", "statusDetails": {"message": "requests.exceptions.ConnectionError: ('Connection aborted.', ConnectionResetError(10054, 'Se ha forzado la interrupción de una conexión existente por el host remoto', None, 10054, None))\n", "trace": "  File \"C:\\Users\\Camilo\\AppData\\Local\\Programs\\Python\\Python312\\Lib\\site-packages\\behave\\model.py\", line 1329, in run\n    match.run(runner.context)\n  File \"C:\\Users\\Camilo\\AppData\\Local\\Programs\\Python\\Python312\\Lib\\site-packages\\behave\\matchers.py\", line 98, in run\n    self.func(context, *args, **kwargs)\n  File \"steps\\user_profile.py\", line 61, in validate_profile\n    response = requests.get(end_point)\n               ^^^^^^^^^^^^^^^^^^^^^^^\n  File \"C:\\Users\\Camilo\\AppData\\Local\\Programs\\Python\\Python312\\Lib\\site-packages\\requests\\api.py\", line 73, in get\n    return request(\"get\", url, params=params, **kwargs)\n           ^^^^^^^^^^^^^^^^^^^^^^^^^^^^^^^^^^^^^^^^^^^^\n  File \"C:\\Users\\Camilo\\AppData\\Local\\Programs\\Python\\Python312\\Lib\\site-packages\\requests\\api.py\", line 59, in request\n    return session.request(method=method, url=url, **kwargs)\n           ^^^^^^^^^^^^^^^^^^^^^^^^^^^^^^^^^^^^^^^^^^^^^^^^^\n  File \"C:\\Users\\Camilo\\AppData\\Local\\Programs\\Python\\Python312\\Lib\\site-packages\\requests\\sessions.py\", line 589, in request\n    resp = self.send(prep, **send_kwargs)\n           ^^^^^^^^^^^^^^^^^^^^^^^^^^^^^^\n  File \"C:\\Users\\Camilo\\AppData\\Local\\Programs\\Python\\Python312\\Lib\\site-packages\\requests\\sessions.py\", line 703, in send\n    r = adapter.send(request, **kwargs)\n        ^^^^^^^^^^^^^^^^^^^^^^^^^^^^^^^\n  File \"C:\\Users\\Camilo\\AppData\\Local\\Programs\\Python\\Python312\\Lib\\site-packages\\requests\\adapters.py\", line 501, in send\n    raise ConnectionError(err, request=request)\n"}, "start": 1715894864454, "stop": 1715894879478}, {"name": "When se envia una solicitud para actualizar la informacion del perfil con id 1, con datos aleatorios", "status": "skipped", "start": 1715894879481, "stop": 1715894879481}, {"name": "Then se recibe una respuesta exitosa despues de actualizar el perfil", "status": "skipped", "start": 1715894879481, "stop": 1715894879481}], "start": 1715894864453, "stop": 1715894879481, "uuid": "73271a66-2d00-42ad-a5b0-7ef1030b9ad6", "historyId": "b3ca619ec2d09ee5c2d100a7db600914", "fullName": "Gestión de Perfiles: Actualizar informacion del perfil", "labels": [{"name": "severity", "value": "normal"}, {"name": "feature", "value": "Gestión de Perfiles"}, {"name": "framework", "value": "behave"}, {"name": "language", "value": "cpython3"}]}